Traceback (most recent call last):
  File "/home/Django/myvenv/lib/python3.6/site-packages/djongo/sql2mongo/query.py", line 807, in __iter__
    yield from iter(self._query)
  File "/home/Django/myvenv/lib/python3.6/site-packages/djongo/sql2mongo/query.py", line 166, in __iter__
    for doc in cursor:
  File "/home/Django/myvenv/lib/python3.6/site-packages/pymongo/cursor.py", line 1207, in next
    if len(self.__data) or self._refresh():
  File "/home/Django/myvenv/lib/python3.6/site-packages/pymongo/cursor.py", line 1100, in _refresh
    self.__session = self.__collection.database.client._ensure_session()
  File "/home/Django/myvenv/lib/python3.6/site-packages/pymongo/mongo_client.py", line 1816, in _ensure_session
    return self.__start_session(True, causal_consistency=False)
  File "/home/Django/myvenv/lib/python3.6/site-packages/pymongo/mongo_client.py", line 1766, in __start_session
    server_session = self._get_server_session()
  File "/home/Django/myvenv/lib/python3.6/site-packages/pymongo/mongo_client.py", line 1802, in _get_server_session
    return self._topology.get_server_session()
  File "/home/Django/myvenv/lib/python3.6/site-packages/pymongo/topology.py", line 488, in get_server_session
    None)
  File "/home/Django/myvenv/lib/python3.6/site-packages/pymongo/topology.py", line 217, in _select_servers_loop
    (self._error_message(selector), timeout, self.description))
pymongo.errors.ServerSelectionTimeoutError: localhost:27017: [Errno 111] Connection refused, Timeout: 30s, Topology Description: <TopologyDescription id: 5fbf6e92616ac1732988e186, topology_type: Single, servers: [<ServerDescription ('localhost', 27017) server_type: Unknown, rtt: None, error=AutoReconnect('localhost:27017: [Errno 111] Connection refused',)>]>

The above exception was the direct cause of the following exception:

Traceback (most recent call last):
  File "/home/Django/myvenv/lib/python3.6/site-packages/djongo/cursor.py", line 65, in fetchmany
    ret.append(self.result.next())
  File "/home/Django/myvenv/lib/python3.6/site-packages/djongo/sql2mongo/query.py", line 796, in __next__
    result = next(self._result_generator)
  File "/home/Django/myvenv/lib/python3.6/site-packages/djongo/sql2mongo/query.py", line 829, in __iter__
    raise exe from e
djongo.exceptions.SQLDecodeError: 

	Keyword: FAILED SQL: SELECT "parsed_data_corona_prevent_notice"."id", "parsed_data_corona_prevent_notice"."title", "parsed_data_corona_prevent_notice"."link", "parsed_data_corona_prevent_notice"."date" FROM "parsed_data_corona_prevent_notice"
Params: ()
Version: 1.3.3
	Sub SQL: None
	FAILED SQL: None
	Params: None
	Version: None

The above exception was the direct cause of the following exception:

Traceback (most recent call last):
  File "/home/Django/myvenv/lib/python3.6/site-packages/django/db/utils.py", line 97, in inner
    return func(*args, **kwargs)
  File "/home/Django/myvenv/lib/python3.6/site-packages/djongo/cursor.py", line 70, in fetchmany
    raise db_exe from e
djongo.database.DatabaseError

The above exception was the direct cause of the following exception:

Traceback (most recent call last):
  File "/home/Django/notice_parser.py", line 72, in <module>
    notice_crawler()
  File "/home/Django/notice_parser.py", line 42, in notice_crawler
    last_notice = DB_list[k].objects.filter(date=temp[len(temp)-1].date)
  File "/home/Django/myvenv/lib/python3.6/site-packages/django/db/models/query.py", line 258, in __len__
    self._fetch_all()
  File "/home/Django/myvenv/lib/python3.6/site-packages/django/db/models/query.py", line 1261, in _fetch_all
    self._result_cache = list(self._iterable_class(self))
  File "/home/Django/myvenv/lib/python3.6/site-packages/django/db/models/query.py", line 57, in __iter__
    results = compiler.execute_sql(chunked_fetch=self.chunked_fetch, chunk_size=self.chunk_size)
  File "/home/Django/myvenv/lib/python3.6/site-packages/django/db/models/sql/compiler.py", line 1184, in execute_sql
    return list(result)
  File "/home/Django/myvenv/lib/python3.6/site-packages/django/db/models/sql/compiler.py", line 1583, in cursor_iter
    for rows in iter((lambda: cursor.fetchmany(itersize)), sentinel):
  File "/home/Django/myvenv/lib/python3.6/site-packages/django/db/models/sql/compiler.py", line 1583, in <lambda>
    for rows in iter((lambda: cursor.fetchmany(itersize)), sentinel):
  File "/home/Django/myvenv/lib/python3.6/site-packages/django/db/utils.py", line 97, in inner
    return func(*args, **kwargs)
  File "/home/Django/myvenv/lib/python3.6/site-packages/django/db/utils.py", line 90, in __exit__
    raise dj_exc_value.with_traceback(traceback) from exc_value
  File "/home/Django/myvenv/lib/python3.6/site-packages/django/db/utils.py", line 97, in inner
    return func(*args, **kwargs)
  File "/home/Django/myvenv/lib/python3.6/site-packages/djongo/cursor.py", line 70, in fetchmany
    raise db_exe from e
django.db.utils.DatabaseError
Traceback (most recent call last):
  File "/home/Django/myvenv/lib/python3.6/site-packages/djongo/sql2mongo/query.py", line 807, in __iter__
    yield from iter(self._query)
  File "/home/Django/myvenv/lib/python3.6/site-packages/djongo/sql2mongo/query.py", line 166, in __iter__
    for doc in cursor:
  File "/home/Django/myvenv/lib/python3.6/site-packages/pymongo/cursor.py", line 1207, in next
    if len(self.__data) or self._refresh():
  File "/home/Django/myvenv/lib/python3.6/site-packages/pymongo/cursor.py", line 1100, in _refresh
    self.__session = self.__collection.database.client._ensure_session()
  File "/home/Django/myvenv/lib/python3.6/site-packages/pymongo/mongo_client.py", line 1816, in _ensure_session
    return self.__start_session(True, causal_consistency=False)
  File "/home/Django/myvenv/lib/python3.6/site-packages/pymongo/mongo_client.py", line 1766, in __start_session
    server_session = self._get_server_session()
  File "/home/Django/myvenv/lib/python3.6/site-packages/pymongo/mongo_client.py", line 1802, in _get_server_session
    return self._topology.get_server_session()
  File "/home/Django/myvenv/lib/python3.6/site-packages/pymongo/topology.py", line 488, in get_server_session
    None)
  File "/home/Django/myvenv/lib/python3.6/site-packages/pymongo/topology.py", line 217, in _select_servers_loop
    (self._error_message(selector), timeout, self.description))
pymongo.errors.ServerSelectionTimeoutError: localhost:27017: [Errno 111] Connection refused, Timeout: 30s, Topology Description: <TopologyDescription id: 5fbf6e92996dfe95764bae9f, topology_type: Single, servers: [<ServerDescription ('localhost', 27017) server_type: Unknown, rtt: None, error=AutoReconnect('localhost:27017: [Errno 111] Connection refused',)>]>

The above exception was the direct cause of the following exception:

Traceback (most recent call last):
  File "/home/Django/myvenv/lib/python3.6/site-packages/djongo/cursor.py", line 65, in fetchmany
    ret.append(self.result.next())
  File "/home/Django/myvenv/lib/python3.6/site-packages/djongo/sql2mongo/query.py", line 796, in __next__
    result = next(self._result_generator)
  File "/home/Django/myvenv/lib/python3.6/site-packages/djongo/sql2mongo/query.py", line 829, in __iter__
    raise exe from e
djongo.exceptions.SQLDecodeError: 

	Keyword: FAILED SQL: SELECT "parsed_data_corona_prevent_notice"."id", "parsed_data_corona_prevent_notice"."title", "parsed_data_corona_prevent_notice"."link", "parsed_data_corona_prevent_notice"."date" FROM "parsed_data_corona_prevent_notice"
Params: ()
Version: 1.3.3
	Sub SQL: None
	FAILED SQL: None
	Params: None
	Version: None

The above exception was the direct cause of the following exception:

Traceback (most recent call last):
  File "/home/Django/myvenv/lib/python3.6/site-packages/django/db/utils.py", line 97, in inner
    return func(*args, **kwargs)
  File "/home/Django/myvenv/lib/python3.6/site-packages/djongo/cursor.py", line 70, in fetchmany
    raise db_exe from e
djongo.database.DatabaseError

The above exception was the direct cause of the following exception:

Traceback (most recent call last):
  File "/home/Django/notice_parser.py", line 72, in <module>
    notice_crawler()
  File "/home/Django/notice_parser.py", line 42, in notice_crawler
    last_notice = DB_list[k].objects.filter(date=temp[len(temp)-1].date)
  File "/home/Django/myvenv/lib/python3.6/site-packages/django/db/models/query.py", line 258, in __len__
    self._fetch_all()
  File "/home/Django/myvenv/lib/python3.6/site-packages/django/db/models/query.py", line 1261, in _fetch_all
    self._result_cache = list(self._iterable_class(self))
  File "/home/Django/myvenv/lib/python3.6/site-packages/django/db/models/query.py", line 57, in __iter__
    results = compiler.execute_sql(chunked_fetch=self.chunked_fetch, chunk_size=self.chunk_size)
  File "/home/Django/myvenv/lib/python3.6/site-packages/django/db/models/sql/compiler.py", line 1184, in execute_sql
    return list(result)
  File "/home/Django/myvenv/lib/python3.6/site-packages/django/db/models/sql/compiler.py", line 1583, in cursor_iter
    for rows in iter((lambda: cursor.fetchmany(itersize)), sentinel):
  File "/home/Django/myvenv/lib/python3.6/site-packages/django/db/models/sql/compiler.py", line 1583, in <lambda>
    for rows in iter((lambda: cursor.fetchmany(itersize)), sentinel):
  File "/home/Django/myvenv/lib/python3.6/site-packages/django/db/utils.py", line 97, in inner
    return func(*args, **kwargs)
  File "/home/Django/myvenv/lib/python3.6/site-packages/django/db/utils.py", line 90, in __exit__
    raise dj_exc_value.with_traceback(traceback) from exc_value
  File "/home/Django/myvenv/lib/python3.6/site-packages/django/db/utils.py", line 97, in inner
    return func(*args, **kwargs)
  File "/home/Django/myvenv/lib/python3.6/site-packages/djongo/cursor.py", line 70, in fetchmany
    raise db_exe from e
django.db.utils.DatabaseError
Traceback (most recent call last):
  File "/home/Django/myvenv/lib/python3.6/site-packages/djongo/sql2mongo/query.py", line 807, in __iter__
    yield from iter(self._query)
  File "/home/Django/myvenv/lib/python3.6/site-packages/djongo/sql2mongo/query.py", line 166, in __iter__
    for doc in cursor:
  File "/home/Django/myvenv/lib/python3.6/site-packages/pymongo/cursor.py", line 1207, in next
    if len(self.__data) or self._refresh():
  File "/home/Django/myvenv/lib/python3.6/site-packages/pymongo/cursor.py", line 1100, in _refresh
    self.__session = self.__collection.database.client._ensure_session()
  File "/home/Django/myvenv/lib/python3.6/site-packages/pymongo/mongo_client.py", line 1816, in _ensure_session
    return self.__start_session(True, causal_consistency=False)
  File "/home/Django/myvenv/lib/python3.6/site-packages/pymongo/mongo_client.py", line 1766, in __start_session
    server_session = self._get_server_session()
  File "/home/Django/myvenv/lib/python3.6/site-packages/pymongo/mongo_client.py", line 1802, in _get_server_session
    return self._topology.get_server_session()
  File "/home/Django/myvenv/lib/python3.6/site-packages/pymongo/topology.py", line 488, in get_server_session
    None)
  File "/home/Django/myvenv/lib/python3.6/site-packages/pymongo/topology.py", line 217, in _select_servers_loop
    (self._error_message(selector), timeout, self.description))
pymongo.errors.ServerSelectionTimeoutError: localhost:27017: [Errno 111] Connection refused, Timeout: 30s, Topology Description: <TopologyDescription id: 5fbf6e93932648c4e5106ad5, topology_type: Single, servers: [<ServerDescription ('localhost', 27017) server_type: Unknown, rtt: None, error=AutoReconnect('localhost:27017: [Errno 111] Connection refused',)>]>

The above exception was the direct cause of the following exception:

Traceback (most recent call last):
  File "/home/Django/myvenv/lib/python3.6/site-packages/djongo/cursor.py", line 65, in fetchmany
    ret.append(self.result.next())
  File "/home/Django/myvenv/lib/python3.6/site-packages/djongo/sql2mongo/query.py", line 796, in __next__
    result = next(self._result_generator)
  File "/home/Django/myvenv/lib/python3.6/site-packages/djongo/sql2mongo/query.py", line 829, in __iter__
    raise exe from e
djongo.exceptions.SQLDecodeError: 

	Keyword: FAILED SQL: SELECT "parsed_data_corona_prevent_notice"."id", "parsed_data_corona_prevent_notice"."title", "parsed_data_corona_prevent_notice"."link", "parsed_data_corona_prevent_notice"."date" FROM "parsed_data_corona_prevent_notice"
Params: ()
Version: 1.3.3
	Sub SQL: None
	FAILED SQL: None
	Params: None
	Version: None

The above exception was the direct cause of the following exception:

Traceback (most recent call last):
  File "/home/Django/myvenv/lib/python3.6/site-packages/django/db/utils.py", line 97, in inner
    return func(*args, **kwargs)
  File "/home/Django/myvenv/lib/python3.6/site-packages/djongo/cursor.py", line 70, in fetchmany
    raise db_exe from e
djongo.database.DatabaseError

The above exception was the direct cause of the following exception:

Traceback (most recent call last):
  File "/home/Django/notice_parser.py", line 72, in <module>
    notice_crawler()
  File "/home/Django/notice_parser.py", line 42, in notice_crawler
    last_notice = DB_list[k].objects.filter(date=temp[len(temp)-1].date)
  File "/home/Django/myvenv/lib/python3.6/site-packages/django/db/models/query.py", line 258, in __len__
    self._fetch_all()
  File "/home/Django/myvenv/lib/python3.6/site-packages/django/db/models/query.py", line 1261, in _fetch_all
    self._result_cache = list(self._iterable_class(self))
  File "/home/Django/myvenv/lib/python3.6/site-packages/django/db/models/query.py", line 57, in __iter__
    results = compiler.execute_sql(chunked_fetch=self.chunked_fetch, chunk_size=self.chunk_size)
  File "/home/Django/myvenv/lib/python3.6/site-packages/django/db/models/sql/compiler.py", line 1184, in execute_sql
    return list(result)
  File "/home/Django/myvenv/lib/python3.6/site-packages/django/db/models/sql/compiler.py", line 1583, in cursor_iter
    for rows in iter((lambda: cursor.fetchmany(itersize)), sentinel):
  File "/home/Django/myvenv/lib/python3.6/site-packages/django/db/models/sql/compiler.py", line 1583, in <lambda>
    for rows in iter((lambda: cursor.fetchmany(itersize)), sentinel):
  File "/home/Django/myvenv/lib/python3.6/site-packages/django/db/utils.py", line 97, in inner
    return func(*args, **kwargs)
  File "/home/Django/myvenv/lib/python3.6/site-packages/django/db/utils.py", line 90, in __exit__
    raise dj_exc_value.with_traceback(traceback) from exc_value
  File "/home/Django/myvenv/lib/python3.6/site-packages/django/db/utils.py", line 97, in inner
    return func(*args, **kwargs)
  File "/home/Django/myvenv/lib/python3.6/site-packages/djongo/cursor.py", line 70, in fetchmany
    raise db_exe from e
django.db.utils.DatabaseError
Traceback (most recent call last):
  File "/home/Django/notice_parser.py", line 8, in <module>
    django.setup()
  File "/home/Django/myvenv/lib/python3.6/site-packages/django/__init__.py", line 19, in setup
    configure_logging(settings.LOGGING_CONFIG, settings.LOGGING)
  File "/home/Django/myvenv/lib/python3.6/site-packages/django/conf/__init__.py", line 76, in __getattr__
    self._setup(name)
  File "/home/Django/myvenv/lib/python3.6/site-packages/django/conf/__init__.py", line 63, in _setup
    self._wrapped = Settings(settings_module)
  File "/home/Django/myvenv/lib/python3.6/site-packages/django/conf/__init__.py", line 142, in __init__
    mod = importlib.import_module(self.SETTINGS_MODULE)
  File "/usr/lib/python3.6/importlib/__init__.py", line 126, in import_module
    return _bootstrap._gcd_import(name[level:], package, level)
  File "<frozen importlib._bootstrap>", line 994, in _gcd_import
  File "<frozen importlib._bootstrap>", line 971, in _find_and_load
  File "<frozen importlib._bootstrap>", line 955, in _find_and_load_unlocked
  File "<frozen importlib._bootstrap>", line 665, in _load_unlocked
  File "<frozen importlib._bootstrap_external>", line 678, in exec_module
  File "<frozen importlib._bootstrap>", line 219, in _call_with_frames_removed
  File "/home/Django/bot/settings.py", line 15, in <module>
    import pymongo
  File "/home/Django/myvenv/lib/python3.6/site-packages/pymongo/__init__.py", line 91, in <module>
    from pymongo.mongo_client import MongoClient
ModuleNotFoundError: No module named 'pymongo.mongo_client'
Traceback (most recent call last):
  File "/home/Django/notice_parser.py", line 8, in <module>
    django.setup()
  File "/home/Django/myvenv/lib/python3.6/site-packages/django/__init__.py", line 19, in setup
    configure_logging(settings.LOGGING_CONFIG, settings.LOGGING)
  File "/home/Django/myvenv/lib/python3.6/site-packages/django/conf/__init__.py", line 76, in __getattr__
    self._setup(name)
  File "/home/Django/myvenv/lib/python3.6/site-packages/django/conf/__init__.py", line 63, in _setup
    self._wrapped = Settings(settings_module)
  File "/home/Django/myvenv/lib/python3.6/site-packages/django/conf/__init__.py", line 142, in __init__
    mod = importlib.import_module(self.SETTINGS_MODULE)
  File "/usr/lib/python3.6/importlib/__init__.py", line 126, in import_module
    return _bootstrap._gcd_import(name[level:], package, level)
  File "<frozen importlib._bootstrap>", line 994, in _gcd_import
  File "<frozen importlib._bootstrap>", line 971, in _find_and_load
  File "<frozen importlib._bootstrap>", line 955, in _find_and_load_unlocked
  File "<frozen importlib._bootstrap>", line 665, in _load_unlocked
  File "<frozen importlib._bootstrap_external>", line 678, in exec_module
  File "<frozen importlib._bootstrap>", line 219, in _call_with_frames_removed
  File "/home/Django/bot/settings.py", line 15, in <module>
    import pymongo
  File "/home/Django/myvenv/lib/python3.6/site-packages/pymongo/__init__.py", line 91, in <module>
    from pymongo.mongo_client import MongoClient
ModuleNotFoundError: No module named 'pymongo.mongo_client'
Traceback (most recent call last):
  File "/home/Django/notice_parser.py", line 8, in <module>
    django.setup()
  File "/home/Django/myvenv/lib/python3.6/site-packages/django/__init__.py", line 19, in setup
    configure_logging(settings.LOGGING_CONFIG, settings.LOGGING)
  File "/home/Django/myvenv/lib/python3.6/site-packages/django/conf/__init__.py", line 76, in __getattr__
    self._setup(name)
  File "/home/Django/myvenv/lib/python3.6/site-packages/django/conf/__init__.py", line 63, in _setup
    self._wrapped = Settings(settings_module)
  File "/home/Django/myvenv/lib/python3.6/site-packages/django/conf/__init__.py", line 142, in __init__
    mod = importlib.import_module(self.SETTINGS_MODULE)
  File "/usr/lib/python3.6/importlib/__init__.py", line 126, in import_module
    return _bootstrap._gcd_import(name[level:], package, level)
  File "<frozen importlib._bootstrap>", line 994, in _gcd_import
  File "<frozen importlib._bootstrap>", line 971, in _find_and_load
  File "<frozen importlib._bootstrap>", line 955, in _find_and_load_unlocked
  File "<frozen importlib._bootstrap>", line 665, in _load_unlocked
  File "<frozen importlib._bootstrap_external>", line 678, in exec_module
  File "<frozen importlib._bootstrap>", line 219, in _call_with_frames_removed
  File "/home/Django/bot/settings.py", line 15, in <module>
    import pymongo
  File "/home/Django/myvenv/lib/python3.6/site-packages/pymongo/__init__.py", line 91, in <module>
    from pymongo.mongo_client import MongoClient
ModuleNotFoundError: No module named 'pymongo.mongo_client'
Traceback (most recent call last):
  File "/home/Django/myvenv/lib/python3.6/site-packages/djongo/sql2mongo/query.py", line 807, in __iter__
    yield from iter(self._query)
  File "/home/Django/myvenv/lib/python3.6/site-packages/djongo/sql2mongo/query.py", line 166, in __iter__
    for doc in cursor:
  File "/home/Django/myvenv/lib/python3.6/site-packages/pymongo/cursor.py", line 1207, in next
    if len(self.__data) or self._refresh():
  File "/home/Django/myvenv/lib/python3.6/site-packages/pymongo/cursor.py", line 1100, in _refresh
    self.__session = self.__collection.database.client._ensure_session()
  File "/home/Django/myvenv/lib/python3.6/site-packages/pymongo/mongo_client.py", line 1816, in _ensure_session
    return self.__start_session(True, causal_consistency=False)
  File "/home/Django/myvenv/lib/python3.6/site-packages/pymongo/mongo_client.py", line 1766, in __start_session
    server_session = self._get_server_session()
  File "/home/Django/myvenv/lib/python3.6/site-packages/pymongo/mongo_client.py", line 1802, in _get_server_session
    return self._topology.get_server_session()
  File "/home/Django/myvenv/lib/python3.6/site-packages/pymongo/topology.py", line 488, in get_server_session
    None)
  File "/home/Django/myvenv/lib/python3.6/site-packages/pymongo/topology.py", line 217, in _select_servers_loop
    (self._error_message(selector), timeout, self.description))
pymongo.errors.ServerSelectionTimeoutError: localhost:27017: [Errno 111] Connection refused, Timeout: 30s, Topology Description: <TopologyDescription id: 5fc0c01328ab95c5c7e972d5, topology_type: Single, servers: [<ServerDescription ('localhost', 27017) server_type: Unknown, rtt: None, error=AutoReconnect('localhost:27017: [Errno 111] Connection refused',)>]>

The above exception was the direct cause of the following exception:

Traceback (most recent call last):
  File "/home/Django/myvenv/lib/python3.6/site-packages/djongo/cursor.py", line 65, in fetchmany
    ret.append(self.result.next())
  File "/home/Django/myvenv/lib/python3.6/site-packages/djongo/sql2mongo/query.py", line 796, in __next__
    result = next(self._result_generator)
  File "/home/Django/myvenv/lib/python3.6/site-packages/djongo/sql2mongo/query.py", line 829, in __iter__
    raise exe from e
djongo.exceptions.SQLDecodeError: 

	Keyword: FAILED SQL: SELECT "parsed_data_corona_prevent_notice"."id", "parsed_data_corona_prevent_notice"."title", "parsed_data_corona_prevent_notice"."link", "parsed_data_corona_prevent_notice"."date" FROM "parsed_data_corona_prevent_notice"
Params: ()
Version: 1.3.3
	Sub SQL: None
	FAILED SQL: None
	Params: None
	Version: None

The above exception was the direct cause of the following exception:

Traceback (most recent call last):
  File "/home/Django/myvenv/lib/python3.6/site-packages/django/db/utils.py", line 97, in inner
    return func(*args, **kwargs)
  File "/home/Django/myvenv/lib/python3.6/site-packages/djongo/cursor.py", line 70, in fetchmany
    raise db_exe from e
djongo.database.DatabaseError

The above exception was the direct cause of the following exception:

Traceback (most recent call last):
  File "/home/Django/notice_parser.py", line 72, in <module>
    notice_crawler()
  File "/home/Django/notice_parser.py", line 42, in notice_crawler
    last_notice = DB_list[k].objects.filter(date=temp[len(temp)-1].date)
  File "/home/Django/myvenv/lib/python3.6/site-packages/django/db/models/query.py", line 258, in __len__
    self._fetch_all()
  File "/home/Django/myvenv/lib/python3.6/site-packages/django/db/models/query.py", line 1261, in _fetch_all
    self._result_cache = list(self._iterable_class(self))
  File "/home/Django/myvenv/lib/python3.6/site-packages/django/db/models/query.py", line 57, in __iter__
    results = compiler.execute_sql(chunked_fetch=self.chunked_fetch, chunk_size=self.chunk_size)
  File "/home/Django/myvenv/lib/python3.6/site-packages/django/db/models/sql/compiler.py", line 1184, in execute_sql
    return list(result)
  File "/home/Django/myvenv/lib/python3.6/site-packages/django/db/models/sql/compiler.py", line 1583, in cursor_iter
    for rows in iter((lambda: cursor.fetchmany(itersize)), sentinel):
  File "/home/Django/myvenv/lib/python3.6/site-packages/django/db/models/sql/compiler.py", line 1583, in <lambda>
    for rows in iter((lambda: cursor.fetchmany(itersize)), sentinel):
  File "/home/Django/myvenv/lib/python3.6/site-packages/django/db/utils.py", line 97, in inner
    return func(*args, **kwargs)
  File "/home/Django/myvenv/lib/python3.6/site-packages/django/db/utils.py", line 90, in __exit__
    raise dj_exc_value.with_traceback(traceback) from exc_value
  File "/home/Django/myvenv/lib/python3.6/site-packages/django/db/utils.py", line 97, in inner
    return func(*args, **kwargs)
  File "/home/Django/myvenv/lib/python3.6/site-packages/djongo/cursor.py", line 70, in fetchmany
    raise db_exe from e
django.db.utils.DatabaseError
Traceback (most recent call last):
  File "/home/Django/myvenv/lib/python3.6/site-packages/djongo/sql2mongo/query.py", line 807, in __iter__
    yield from iter(self._query)
  File "/home/Django/myvenv/lib/python3.6/site-packages/djongo/sql2mongo/query.py", line 166, in __iter__
    for doc in cursor:
  File "/home/Django/myvenv/lib/python3.6/site-packages/pymongo/cursor.py", line 1207, in next
    if len(self.__data) or self._refresh():
  File "/home/Django/myvenv/lib/python3.6/site-packages/pymongo/cursor.py", line 1100, in _refresh
    self.__session = self.__collection.database.client._ensure_session()
  File "/home/Django/myvenv/lib/python3.6/site-packages/pymongo/mongo_client.py", line 1816, in _ensure_session
    return self.__start_session(True, causal_consistency=False)
  File "/home/Django/myvenv/lib/python3.6/site-packages/pymongo/mongo_client.py", line 1766, in __start_session
    server_session = self._get_server_session()
  File "/home/Django/myvenv/lib/python3.6/site-packages/pymongo/mongo_client.py", line 1802, in _get_server_session
    return self._topology.get_server_session()
  File "/home/Django/myvenv/lib/python3.6/site-packages/pymongo/topology.py", line 488, in get_server_session
    None)
  File "/home/Django/myvenv/lib/python3.6/site-packages/pymongo/topology.py", line 217, in _select_servers_loop
    (self._error_message(selector), timeout, self.description))
pymongo.errors.ServerSelectionTimeoutError: localhost:27017: [Errno 111] Connection refused, Timeout: 30s, Topology Description: <TopologyDescription id: 5fc0c013025f429e3b8a5b38, topology_type: Single, servers: [<ServerDescription ('localhost', 27017) server_type: Unknown, rtt: None, error=AutoReconnect('localhost:27017: [Errno 111] Connection refused',)>]>

The above exception was the direct cause of the following exception:

Traceback (most recent call last):
  File "/home/Django/myvenv/lib/python3.6/site-packages/djongo/cursor.py", line 65, in fetchmany
    ret.append(self.result.next())
  File "/home/Django/myvenv/lib/python3.6/site-packages/djongo/sql2mongo/query.py", line 796, in __next__
    result = next(self._result_generator)
  File "/home/Django/myvenv/lib/python3.6/site-packages/djongo/sql2mongo/query.py", line 829, in __iter__
    raise exe from e
djongo.exceptions.SQLDecodeError: 

	Keyword: FAILED SQL: SELECT "parsed_data_corona_prevent_notice"."id", "parsed_data_corona_prevent_notice"."title", "parsed_data_corona_prevent_notice"."link", "parsed_data_corona_prevent_notice"."date" FROM "parsed_data_corona_prevent_notice"
Params: ()
Version: 1.3.3
	Sub SQL: None
	FAILED SQL: None
	Params: None
	Version: None

The above exception was the direct cause of the following exception:

Traceback (most recent call last):
  File "/home/Django/myvenv/lib/python3.6/site-packages/django/db/utils.py", line 97, in inner
    return func(*args, **kwargs)
  File "/home/Django/myvenv/lib/python3.6/site-packages/djongo/cursor.py", line 70, in fetchmany
    raise db_exe from e
djongo.database.DatabaseError

The above exception was the direct cause of the following exception:

Traceback (most recent call last):
  File "/home/Django/notice_parser.py", line 72, in <module>
    notice_crawler()
  File "/home/Django/notice_parser.py", line 42, in notice_crawler
    last_notice = DB_list[k].objects.filter(date=temp[len(temp)-1].date)
  File "/home/Django/myvenv/lib/python3.6/site-packages/django/db/models/query.py", line 258, in __len__
    self._fetch_all()
  File "/home/Django/myvenv/lib/python3.6/site-packages/django/db/models/query.py", line 1261, in _fetch_all
    self._result_cache = list(self._iterable_class(self))
  File "/home/Django/myvenv/lib/python3.6/site-packages/django/db/models/query.py", line 57, in __iter__
    results = compiler.execute_sql(chunked_fetch=self.chunked_fetch, chunk_size=self.chunk_size)
  File "/home/Django/myvenv/lib/python3.6/site-packages/django/db/models/sql/compiler.py", line 1184, in execute_sql
    return list(result)
  File "/home/Django/myvenv/lib/python3.6/site-packages/django/db/models/sql/compiler.py", line 1583, in cursor_iter
    for rows in iter((lambda: cursor.fetchmany(itersize)), sentinel):
  File "/home/Django/myvenv/lib/python3.6/site-packages/django/db/models/sql/compiler.py", line 1583, in <lambda>
    for rows in iter((lambda: cursor.fetchmany(itersize)), sentinel):
  File "/home/Django/myvenv/lib/python3.6/site-packages/django/db/utils.py", line 97, in inner
    return func(*args, **kwargs)
  File "/home/Django/myvenv/lib/python3.6/site-packages/django/db/utils.py", line 90, in __exit__
    raise dj_exc_value.with_traceback(traceback) from exc_value
  File "/home/Django/myvenv/lib/python3.6/site-packages/django/db/utils.py", line 97, in inner
    return func(*args, **kwargs)
  File "/home/Django/myvenv/lib/python3.6/site-packages/djongo/cursor.py", line 70, in fetchmany
    raise db_exe from e
django.db.utils.DatabaseError
Traceback (most recent call last):
  File "/home/Django/myvenv/lib/python3.6/site-packages/djongo/sql2mongo/query.py", line 807, in __iter__
    yield from iter(self._query)
  File "/home/Django/myvenv/lib/python3.6/site-packages/djongo/sql2mongo/query.py", line 166, in __iter__
    for doc in cursor:
  File "/home/Django/myvenv/lib/python3.6/site-packages/pymongo/cursor.py", line 1207, in next
    if len(self.__data) or self._refresh():
  File "/home/Django/myvenv/lib/python3.6/site-packages/pymongo/cursor.py", line 1100, in _refresh
    self.__session = self.__collection.database.client._ensure_session()
  File "/home/Django/myvenv/lib/python3.6/site-packages/pymongo/mongo_client.py", line 1816, in _ensure_session
    return self.__start_session(True, causal_consistency=False)
  File "/home/Django/myvenv/lib/python3.6/site-packages/pymongo/mongo_client.py", line 1766, in __start_session
    server_session = self._get_server_session()
  File "/home/Django/myvenv/lib/python3.6/site-packages/pymongo/mongo_client.py", line 1802, in _get_server_session
    return self._topology.get_server_session()
  File "/home/Django/myvenv/lib/python3.6/site-packages/pymongo/topology.py", line 488, in get_server_session
    None)
  File "/home/Django/myvenv/lib/python3.6/site-packages/pymongo/topology.py", line 217, in _select_servers_loop
    (self._error_message(selector), timeout, self.description))
pymongo.errors.ServerSelectionTimeoutError: localhost:27017: [Errno 111] Connection refused, Timeout: 30s, Topology Description: <TopologyDescription id: 5fc0c013c5998fa4407d1aa1, topology_type: Single, servers: [<ServerDescription ('localhost', 27017) server_type: Unknown, rtt: None, error=AutoReconnect('localhost:27017: [Errno 111] Connection refused',)>]>

The above exception was the direct cause of the following exception:

Traceback (most recent call last):
  File "/home/Django/myvenv/lib/python3.6/site-packages/djongo/cursor.py", line 65, in fetchmany
    ret.append(self.result.next())
  File "/home/Django/myvenv/lib/python3.6/site-packages/djongo/sql2mongo/query.py", line 796, in __next__
    result = next(self._result_generator)
  File "/home/Django/myvenv/lib/python3.6/site-packages/djongo/sql2mongo/query.py", line 829, in __iter__
    raise exe from e
djongo.exceptions.SQLDecodeError: 

	Keyword: FAILED SQL: SELECT "parsed_data_corona_prevent_notice"."id", "parsed_data_corona_prevent_notice"."title", "parsed_data_corona_prevent_notice"."link", "parsed_data_corona_prevent_notice"."date" FROM "parsed_data_corona_prevent_notice"
Params: ()
Version: 1.3.3
	Sub SQL: None
	FAILED SQL: None
	Params: None
	Version: None

The above exception was the direct cause of the following exception:

Traceback (most recent call last):
  File "/home/Django/myvenv/lib/python3.6/site-packages/django/db/utils.py", line 97, in inner
    return func(*args, **kwargs)
  File "/home/Django/myvenv/lib/python3.6/site-packages/djongo/cursor.py", line 70, in fetchmany
    raise db_exe from e
djongo.database.DatabaseError

The above exception was the direct cause of the following exception:

Traceback (most recent call last):
  File "/home/Django/notice_parser.py", line 72, in <module>
    notice_crawler()
  File "/home/Django/notice_parser.py", line 42, in notice_crawler
    last_notice = DB_list[k].objects.filter(date=temp[len(temp)-1].date)
  File "/home/Django/myvenv/lib/python3.6/site-packages/django/db/models/query.py", line 258, in __len__
    self._fetch_all()
  File "/home/Django/myvenv/lib/python3.6/site-packages/django/db/models/query.py", line 1261, in _fetch_all
    self._result_cache = list(self._iterable_class(self))
  File "/home/Django/myvenv/lib/python3.6/site-packages/django/db/models/query.py", line 57, in __iter__
    results = compiler.execute_sql(chunked_fetch=self.chunked_fetch, chunk_size=self.chunk_size)
  File "/home/Django/myvenv/lib/python3.6/site-packages/django/db/models/sql/compiler.py", line 1184, in execute_sql
    return list(result)
  File "/home/Django/myvenv/lib/python3.6/site-packages/django/db/models/sql/compiler.py", line 1583, in cursor_iter
    for rows in iter((lambda: cursor.fetchmany(itersize)), sentinel):
  File "/home/Django/myvenv/lib/python3.6/site-packages/django/db/models/sql/compiler.py", line 1583, in <lambda>
    for rows in iter((lambda: cursor.fetchmany(itersize)), sentinel):
  File "/home/Django/myvenv/lib/python3.6/site-packages/django/db/utils.py", line 97, in inner
    return func(*args, **kwargs)
  File "/home/Django/myvenv/lib/python3.6/site-packages/django/db/utils.py", line 90, in __exit__
    raise dj_exc_value.with_traceback(traceback) from exc_value
  File "/home/Django/myvenv/lib/python3.6/site-packages/django/db/utils.py", line 97, in inner
    return func(*args, **kwargs)
  File "/home/Django/myvenv/lib/python3.6/site-packages/djongo/cursor.py", line 70, in fetchmany
    raise db_exe from e
django.db.utils.DatabaseError
Traceback (most recent call last):
  File "/home/Django/notice_parser.py", line 77, in <module>
    notice_crawler()
  File "/home/Django/notice_parser.py", line 41, in notice_crawler
    print(a[b]['name'])
  File "/home/Django/myvenv/lib/python3.6/site-packages/pymongo/cursor.py", line 641, in __getitem__
    raise IndexError("Cursor instances do not support negative "
IndexError: Cursor instances do not support negative indices
Traceback (most recent call last):
  File "/home/Django/notice_parser.py", line 77, in <module>
    notice_crawler()
  File "/home/Django/notice_parser.py", line 41, in notice_crawler
    print(a[b]['name'])
  File "/home/Django/myvenv/lib/python3.6/site-packages/pymongo/cursor.py", line 641, in __getitem__
    raise IndexError("Cursor instances do not support negative "
IndexError: Cursor instances do not support negative indices
Traceback (most recent call last):
  File "/home/Django/notice_parser.py", line 77, in <module>
    notice_crawler()
  File "/home/Django/notice_parser.py", line 41, in notice_crawler
    print(a[b]['name'])
  File "/home/Django/myvenv/lib/python3.6/site-packages/pymongo/cursor.py", line 641, in __getitem__
    raise IndexError("Cursor instances do not support negative "
IndexError: Cursor instances do not support negative indices
